Traceback (most recent call last):
  File "/usr/local/lib/python3.7/dist-packages/jupyter_cache/executors/utils.py", line 56, in single_nb_execution
    record_timing=False,
  File "/usr/local/lib/python3.7/dist-packages/nbclient/client.py", line 1204, in execute
    return NotebookClient(nb=nb, resources=resources, km=km, **kwargs).execute()
  File "/usr/local/lib/python3.7/dist-packages/nbclient/util.py", line 84, in wrapped
    return just_run(coro(*args, **kwargs))
  File "/usr/local/lib/python3.7/dist-packages/nbclient/util.py", line 62, in just_run
    return loop.run_until_complete(coro)
  File "/usr/lib/python3.7/asyncio/base_events.py", line 587, in run_until_complete
    return future.result()
  File "/usr/local/lib/python3.7/dist-packages/nbclient/client.py", line 664, in async_execute
    cell, index, execution_count=self.code_cells_executed + 1
  File "/usr/local/lib/python3.7/dist-packages/nbclient/client.py", line 965, in async_execute_cell
    await self._check_raise_for_error(cell, cell_index, exec_reply)
  File "/usr/local/lib/python3.7/dist-packages/nbclient/client.py", line 862, in _check_raise_for_error
    raise CellExecutionError.from_cell_and_msg(cell, exec_reply_content)
nbclient.exceptions.CellExecutionError: An error occurred while executing the following cell:
------------------
import pandas as pd
import numpy as np
import matplotlib.pyplot as plt
from sklearn import datasets
from sklearn.neighbors import KNeigborsClassifier
from sklearn.metrics import accuracy_score
from sklearn.metrics import classification_report
------------------

[0;31m[0m
[0;31mImportError[0mTraceback (most recent call last)
[0;32m<ipython-input-1-4722997944c3>[0m in [0;36m<module>[0;34m[0m
[1;32m      3[0m [0;32mimport[0m [0mmatplotlib[0m[0;34m.[0m[0mpyplot[0m [0;32mas[0m [0mplt[0m[0;34m[0m[0;34m[0m[0m
[1;32m      4[0m [0;32mfrom[0m [0msklearn[0m [0;32mimport[0m [0mdatasets[0m[0;34m[0m[0;34m[0m[0m
[0;32m----> 5[0;31m [0;32mfrom[0m [0msklearn[0m[0;34m.[0m[0mneighbors[0m [0;32mimport[0m [0mKNeigborsClassifier[0m[0;34m[0m[0;34m[0m[0m
[0m[1;32m      6[0m [0;32mfrom[0m [0msklearn[0m[0;34m.[0m[0mmetrics[0m [0;32mimport[0m [0maccuracy_score[0m[0;34m[0m[0;34m[0m[0m
[1;32m      7[0m [0;32mfrom[0m [0msklearn[0m[0;34m.[0m[0mmetrics[0m [0;32mimport[0m [0mclassification_report[0m[0;34m[0m[0;34m[0m[0m

[0;31mImportError[0m: cannot import name 'KNeigborsClassifier' from 'sklearn.neighbors' (/usr/local/lib/python3.7/dist-packages/sklearn/neighbors/__init__.py)

[0;31m---------------------------------------------------------------------------[0;32m
NOTE: If your import is failing due to a missing package, you can
manually install dependencies using either !pip or !apt.

To view examples of installing some common dependencies, click the
"Open Examples" button below.
[0;31m---------------------------------------------------------------------------[0m

ImportError: cannot import name 'KNeigborsClassifier' from 'sklearn.neighbors' (/usr/local/lib/python3.7/dist-packages/sklearn/neighbors/__init__.py)

